2022-02-04T11:45:27.131143+00:00 app[api]: Release v14 created by user soobsamadi@gmail.com
2022-02-04T11:45:31.422837+00:00 heroku[worker.1]: Restarting
2022-02-04T11:45:31.575864+00:00 heroku[worker.1]: State changed from up to starting
2022-02-04T11:45:32.463265+00:00 heroku[worker.1]: Stopping all processes with SIGTERM
2022-02-04T11:45:32.635514+00:00 app[worker.1]: TERMINATE with 15
2022-02-04T11:45:32.635700+00:00 app[worker.1]: INFO:apscheduler.scheduler:Scheduler has been shut down
2022-02-04T11:45:35.790083+00:00 heroku[worker.1]: Process exited with status 0
2022-02-04T11:45:37.000000+00:00 app[api]: Build succeeded
2022-02-04T11:45:37.412064+00:00 heroku[worker.1]: Starting process with command `python3 main.py`
2022-02-04T11:45:38.277903+00:00 heroku[worker.1]: State changed from starting to up
2022-02-04T11:46:42.715643+00:00 app[worker.1]: [debug] [Daftsex] Extracting URL: https://daftsex.com/watch/-145958185_456243473
2022-02-04T11:46:42.715796+00:00 app[worker.1]: [Daftsex] -145958185_456243473: Downloading webpage
2022-02-04T11:46:43.004399+00:00 app[worker.1]: [Daftsex] -145958185_456243473: Downloading webpage
2022-02-04T11:46:43.241976+00:00 app[worker.1]: ERROR: -145958185_456243473: An extractor error has occurred. (caused by KeyError('cdn_files')); please report this issue on  https://github.com/yt-dlp/yt-dlp , filling out the "Broken site" issue template properly. Confirm you are on the latest version using -U
2022-02-04T11:46:43.243485+00:00 app[worker.1]: Traceback (most recent call last):
2022-02-04T11:46:43.243487+00:00 app[worker.1]:   File "/app/.heroku/python/lib/python3.9/site-packages/yt_dlp/extractor/common.py", line 612, in extract
2022-02-04T11:46:43.243487+00:00 app[worker.1]:     ie_result = self._real_extract(url)
2022-02-04T11:46:43.243488+00:00 app[worker.1]:   File "/app/.heroku/python/lib/python3.9/site-packages/yt_dlp/extractor/daftsex.py", line 56, in _real_extract
2022-02-04T11:46:43.243488+00:00 app[worker.1]:     for format_id, format_data in video_params['video']['cdn_files'].items():
2022-02-04T11:46:43.243489+00:00 app[worker.1]: KeyError: 'cdn_files'
2022-02-04T11:46:43.243489+00:00 app[worker.1]: Traceback (most recent call last):
2022-02-04T11:46:43.243489+00:00 app[worker.1]:   File "/app/.heroku/python/lib/python3.9/site-packages/yt_dlp/extractor/common.py", line 612, in extract
2022-02-04T11:46:43.243489+00:00 app[worker.1]:     ie_result = self._real_extract(url)
2022-02-04T11:46:43.243490+00:00 app[worker.1]:   File "/app/.heroku/python/lib/python3.9/site-packages/yt_dlp/extractor/daftsex.py", line 56, in _real_extract
2022-02-04T11:46:43.243490+00:00 app[worker.1]:     for format_id, format_data in video_params['video']['cdn_files'].items():
2022-02-04T11:46:43.243490+00:00 app[worker.1]: KeyError: 'cdn_files'
2022-02-04T11:46:43.243491+00:00 app[worker.1]: 
2022-02-04T11:46:43.243491+00:00 app[worker.1]: During handling of the above exception, another exception occurred:
2022-02-04T11:46:43.243491+00:00 app[worker.1]: 
2022-02-04T11:46:43.243491+00:00 app[worker.1]: Traceback (most recent call last):
2022-02-04T11:46:43.243491+00:00 app[worker.1]:   File "/app/.heroku/python/lib/python3.9/site-packages/yt_dlp/YoutubeDL.py", line 1381, in wrapper
2022-02-04T11:46:43.243492+00:00 app[worker.1]:     return func(self, *args, **kwargs)
2022-02-04T11:46:43.243492+00:00 app[worker.1]:   File "/app/.heroku/python/lib/python3.9/site-packages/yt_dlp/YoutubeDL.py", line 1451, in __extract_info
2022-02-04T11:46:43.243492+00:00 app[worker.1]:     ie_result = ie.extract(url)
2022-02-04T11:46:43.243492+00:00 app[worker.1]:   File "/app/.heroku/python/lib/python3.9/site-packages/yt_dlp/extractor/common.py", line 642, in extract
2022-02-04T11:46:43.243492+00:00 app[worker.1]:     raise ExtractorError('An extractor error has occurred.', cause=e, video_id=self.get_temp_id(url))
2022-02-04T11:46:43.243493+00:00 app[worker.1]: yt_dlp.utils.ExtractorError: -145958185_456243473: An extractor error has occurred. (caused by KeyError('cdn_files')); please report this issue on  https://github.com/yt-dlp/yt-dlp , filling out the "Broken site" issue template properly. Confirm you are on the latest version using -U
2022-02-04T11:46:43.243493+00:00 app[worker.1]: 
2022-02-04T11:46:42.433307+00:00 app[worker.1]: [debug] Command-line config: ['-vU', '--geo-bypass', '--no-check-certificate', '-o', 'v.mp4', 'https://daftsex.com/watch/-145958185_456243473']
2022-02-04T11:46:42.437312+00:00 app[worker.1]: [debug] Encodings: locale UTF-8, fs utf-8, out utf-8 (No ANSI), err utf-8 (No ANSI), pref UTF-8
2022-02-04T11:46:42.437337+00:00 app[worker.1]: [debug] yt-dlp version 2022.02.04 [c1653e9ef]
2022-02-04T11:46:42.449292+00:00 app[worker.1]: [debug] Python version 3.9.10 (CPython 64bit) - Linux-4.4.0-1097-aws-x86_64-with-glibc2.31
2022-02-04T11:46:42.496598+00:00 app[worker.1]: [debug] exe versions: ffmpeg N-60236-gffb000fff8-static (setts), ffprobe N-60236-gffb000fff8-static
2022-02-04T11:46:42.496800+00:00 app[worker.1]: [debug] Optional libraries: Cryptodome, mutagen, sqlite, websockets
2022-02-04T11:46:42.496801+00:00 app[worker.1]: [debug] Proxy map: {}
2022-02-04T11:46:42.631436+00:00 app[worker.1]: Latest version: 2022.02.04, Current version: 2022.02.04
2022-02-04T11:46:42.631440+00:00 app[worker.1]: yt-dlp is up to date (2022.02.04)